Workbook

Sheet Tasks
A1: ID | B1: Task | C1: Phase | D1: Track | E1: Owner | F1: Start | G1: Due | H1: Est (days) | I1: Depends on | J1: Status | K1: % complete | L1: Actual days | M1: Notes
A2: D0.1 | B2: Confirm Postgres tier and region (B1ms, West US 3); raise the request | C2: 0 - Decisions | D2: Platform | E2: Dev A | F2: 2026-10-12 | G2: 2026-10-12 | H2: 0.25 | J2: Not started | K2: 0
A3: D0.2 | B3: Decide SWA linked-backend vs explicit CORS - spike both, pick one | C3: 0 - Decisions | D3: Application | E3: Dev B | F3: 2026-10-12 | G3: 2026-10-13 | H3: 0.5 | J3: Not started | K3: 0
A4: D0.3 | B4: Start the Azure OpenAI / BAA conversation with legal - long lead | C4: 0 - Decisions | D4: Platform | E4: Dev A | F4: 2026-10-12 | G4: 2026-10-12 | H4: 0.25 | J4: Not started | K4: 0
A5: D0.4 | B5: Agree environment names and the staging story (slot vs second RG) | C5: 0 - Decisions | D5: Both | E5: Dev A + B | F5: 2026-10-13 | G5: 2026-10-13 | H5: 0.25 | J5: Not started | K5: 0
A6: D0.5 | B6: Confirm the pilot runs on the fictional corpus - write the gate down | C6: 0 - Decisions | D6: Both | E6: Dev A + B | F6: 2026-10-13 | G6: 2026-10-13 | H6: 0.25 | J6: Not started | K6: 0
A7: D0.7 | B7: ASK THE CLIENT: data volume, source system, export format, a sample | C7: 0 - Decisions | D7: Both | E7: Dev A + B | F7: 2026-10-12 | G7: 2026-10-13 | H7: 0 | J7: Not started | K7: 0 | M7: COSTS NOTHING, WORTH THE MOST - the answer sizes all of Phase 6
A8: A1.1 | B8: Provision Postgres Flexible Server B1ms, private endpoint, firewall | C8: 1 - Postgres | D8: Platform | E8: Dev A | F8: 2026-10-14 | G8: 2026-10-14 | H8: 0.5 | I8: D0.1 | J8: Not started | K8: 0
A9: A1.2 | B9: Enable PITR (7 day); confirm automated backup schedule | C9: 1 - Postgres | D9: Platform | E9: Dev A | F9: 2026-10-14 | G9: 2026-10-14 | H9: 0.25 | I9: A1.1 | J9: Not started | K9: 0
A10: A1.3 | B10: Create DB, role, least-privilege grants - app user is not owner | C10: 1 - Postgres | D10: Platform | E10: Dev A | F10: 2026-10-15 | G10: 2026-10-15 | H10: 0.5 | I10: A1.1 | J10: Not started | K10: 0
A11: B1.1 | B11: Run all 15 migrations against Postgres; fix dialect assumptions | C11: 1 - Postgres | D11: Application | E11: Dev B | F11: 2026-10-14 | G11: 2026-10-15 | H11: 1 | I11: A1.1 | J11: Not started | K11: 0
A12: B1.2 | B12: Run the full backend suite against Postgres, not SQLite | C12: 1 - Postgres | D12: Application | E12: Dev B | F12: 2026-10-15 | G12: 2026-10-15 | H12: 0.5 | I12: B1.1 | J12: Not started | K12: 0
A13: B1.3 | B13: Corpus loader: ingest into Postgres, repeatable and idempotent | C13: 1 - Postgres | D13: Application | E13: Dev B | F13: 2026-10-15 | G13: 2026-10-16 | H13: 1 | I13: B1.1 | J13: Not started | K13: 0
A14: B1.4 | B14: Decide backup.py's fate - SQLite-only, already no-ops elsewhere | C14: 1 - Postgres | D14: Application | E14: Dev B | F14: 2026-10-16 | G14: 2026-10-16 | H14: 0.25 | I14: B1.1 | J14: Not started | K14: 0
A15: A1.4 | B15: Size the asyncpg pool against the B1ms connection limit | C15: 1 - Postgres | D15: Platform | E15: Dev A | F15: 2026-10-16 | G15: 2026-10-16 | H15: 0.5 | I15: B1.1 | J15: Not started | K15: 0
A16: A1.5 | B16: CI runs the suite against Postgres, not SQLite - service container | C16: 1 - Postgres | D16: Platform | E16: Dev A | F16: 2026-10-16 | G16: 2026-10-16 | H16: 0.5 | I16: B1.2 | J16: Not started | K16: 0 | M16: DO NOT CUT - without it CI tests a database you no longer use
A17: B1.5 | B17: Documented rollback to SQLite if Postgres fails mid-pilot | C17: 1 - Postgres | D17: Application | E17: Dev B | F17: 2026-10-16 | G17: 2026-10-16 | H17: 0.5 | I17: B1.1 | J17: Not started | K17: 0
A18: M1 | B18: MILESTONE: app runs on Postgres, suite green | C18: 1 - Postgres | D18: Both | E18: Dev A + B | F18: 2026-10-16 | G18: 2026-10-16 | H18: 0 | I18: A1.4,B1.3 | J18: Not started | K18: 0
A19: A2.1 | B19: Provision Static Web App (Standard) - nanovox-web | C19: 2 - Split | D19: Platform | E19: Dev A | F19: 2026-10-19 | G19: 2026-10-19 | H19: 0.5 | I19: D0.2 | J19: Not started | K19: 0
A20: A2.2 | B20: Rename/retarget App Service as API-only - nanovox-api | C20: 2 - Split | D20: Platform | E20: Dev A | F20: 2026-10-19 | G20: 2026-10-19 | H20: 0.5 | J20: Not started | K20: 0
A21: A2.3 | B21: Wire SWA linked backend; confirm /api/* proxies same-origin | C21: 2 - Split | D21: Platform | E21: Dev A | F21: 2026-10-20 | G21: 2026-10-20 | H21: 0.5 | I21: A2.1,A2.2 | J21: Not started | K21: 0
A22: B2.1 | B22: Frontend build artefact independent of the backend package | C22: 2 - Split | D22: Application | E22: Dev B | F22: 2026-10-19 | G22: 2026-10-20 | H22: 1 | I22: D0.2 | J22: Not started | K22: 0
A23: B2.2 | B23: CORS middleware + CORS_ORIGINS - fallback if A2.3 fails | C23: 2 - Split | D23: Application | E23: Dev B | F23: 2026-10-20 | G23: 2026-10-21 | H23: 0.75 | I23: A2.3 | J23: Not started | K23: 0 | M23: FALLBACK CUT 3 - disappears on its own if the linked backend works
A24: B2.3 | B24: Keep spa.py working for local/container; test it still serves | C24: 2 - Split | D24: Application | E24: Dev B | F24: 2026-10-21 | G24: 2026-10-21 | H24: 0.5 | J24: Not started | K24: 0
A25: A2.4 | B25: One pipeline, two deploy stages: build both, deploy API then web | C25: 2 - Split | D25: Platform | E25: Dev A | F25: 2026-10-21 | G25: 2026-10-23 | H25: 1.5 | I25: A2.3,B2.1 | J25: Not started | K25: 0
A26: A2.5 | B26: Deploy ordering + rollback: API first, web second, both revertible | C26: 2 - Split | D26: Platform | E26: Dev A | F26: 2026-10-23 | G26: 2026-10-23 | H26: 0.5 | I26: A2.4 | J26: Not started | K26: 0
A27: A2.6 | B27: Authentication after the split - where sign-in lives, SWA vs API | C27: 2 - Split | D27: Platform | E27: Dev A | F27: 2026-10-26 | G27: 2026-10-27 | H27: 1.5 | I27: A2.3 | J27: Not started | K27: 0 | M27: The plan previously never mentioned authentication at all
A28: M2 | B28: MILESTONE: both resources deploy from one pipeline run, signed in | C28: 2 - Split | D28: Both | E28: Dev A + B | F28: 2026-10-27 | G28: 2026-10-27 | H28: 0 | I28: A2.5,B2.2,A2.6 | J28: Not started | K28: 0
A29: A3.1 | B29: Key Vault + system-assigned managed identity on the API | C29: 3 - Hardening | D29: Platform | E29: Dev A | F29: 2026-10-28 | G29: 2026-10-28 | H29: 0.5 | J29: Not started | K29: 0
A30: A3.2 | B30: Move OPENAI_API_KEY and DATABASE_URL to Key Vault references | C30: 3 - Hardening | D30: Platform | E30: Dev A | F30: 2026-10-29 | G30: 2026-10-29 | H30: 0.5 | I30: A3.1 | J30: Not started | K30: 0
A31: A3.3 | B31: Application Insights on the API; connection string via Key Vault | C31: 3 - Hardening | D31: Platform | E31: Dev A | F31: 2026-10-30 | G31: 2026-10-30 | H31: 0.5 | I31: A3.1 | J31: Not started | K31: 0
A32: A3.4 | B32: Staging slot on the API; pipeline deploys to staging then swaps | C32: 3 - Hardening | D32: Platform | E32: Dev A | F32: 2026-11-02 | G32: 2026-11-03 | H32: 1 | I32: A2.4 | J32: Not started | K32: 0 | M32: DO NOT CUT - staging slot is the rollback path
A33: A3.5 | B33: Alerts: availability, 5xx rate, p95 latency, DB connection failures | C33: 3 - Hardening | D33: Platform | E33: Dev A | F33: 2026-11-04 | G33: 2026-11-05 | H33: 0.75 | I33: A3.3 | J33: Not started | K33: 0
A34: B3.1 | B34: Structured request logging with correlation id into App Insights | C34: 3 - Hardening | D34: Application | E34: Dev B | F34: 2026-10-28 | G34: 2026-10-29 | H34: 0.75 | I34: A3.3 | J34: Not started | K34: 0
A35: B3.2 | B35: Health endpoint reports DB and provider reachability for probes | C35: 3 - Hardening | D35: Application | E35: Dev B | F35: 2026-10-29 | G35: 2026-10-30 | H35: 0.5 | J35: Not started | K35: 0
A36: B3.3 | B36: /risk payload 204 KB - split or trim before real volume | C36: 3 - Hardening | D36: Application | E36: Dev B | F36: 2026-11-02 | G36: 2026-11-03 | H36: 1.5 | J36: Not started | K36: 0 | M36: FALLBACK CUT 1 - only if the week-3 check-in is behind. 204 KB works today.
A37: B3.4 | B37: Rate limiting on /insights/generated - it costs money per call | C37: 3 - Hardening | D37: Application | E37: Dev B | F37: 2026-11-06 | G37: 2026-11-06 | H37: 0.5 | J37: Not started | K37: 0
A38: A3.6 | B38: Azure budget alert on the subscription, and on OpenAI spend | C38: 3 - Hardening | D38: Platform | E38: Dev A | F38: 2026-11-09 | G38: 2026-11-09 | H38: 0.25 | J38: Not started | K38: 0
A39: M3 | B39: MILESTONE: staging swap works, telemetry flowing, alerts fire | C39: 3 - Hardening | D39: Both | E39: Dev A + B | F39: 2026-11-06 | G39: 2026-11-06 | H39: 0 | I39: A3.5,B3.4 | J39: Not started | K39: 0
A40: A4.1 | B40: Restore drill: restore Postgres from PITR into a scratch server | C40: 4 - Cutover | D40: Platform | E40: Dev A | F40: 2026-11-09 | G40: 2026-11-09 | H40: 0.75 | I40: A1.2 | J40: Not started | K40: 0 | M40: DO NOT CUT - a pilot without a tested restore is an outage with an audience
...

Sheet Summary
A1: NanoVox Insights - production readiness
A2: 12 Oct - 20 Nov 2026 | 6 weeks | 2 developers, part time | 30 person-days
A4: By phase
A5: Phase | B5: Tasks | C5: Est (days) | D5: Done | E5: In progress | F5: Blocked | G5: % complete
A6: 0 - Decisions | B6: =COUNTIF(Tasks!$C$2:$C$68,$A6) -> 6 | C6: =SUMIF(Tasks!$C$2:$C$68,$A6,Tasks!$H$2:$H$68) -> 1.5 | D6: =COUNTIFS(Tasks!$C$2:$C$68,$A6,Tasks!$J$2:$J$68,"Done") -> 0 | E6: =COUNTIFS(Tasks!$C$2:$C$68,$A6,Tasks!$J$2:$J$68,"In progress") -> 0 | F6: =COUNTIFS(Tasks!$C$2:$C$68,$A6,Tasks!$J$2:$J$68,"Blocked") -> 0 | G6: =IFERROR(SUMIF(Tasks!$C$2:$C$68,$A6,Tasks!$K$2:$K$68)/B6,0) -> 0
A7: 1 - Postgres | B7: =COUNTIF(Tasks!$C$2:$C$68,$A7) -> 11 | C7: =SUMIF(Tasks!$C$2:$C$68,$A7,Tasks!$H$2:$H$68) -> 5.5 | D7: =COUNTIFS(Tasks!$C$2:$C$68,$A7,Tasks!$J$2:$J$68,"Done") -> 0 | E7: =COUNTIFS(Tasks!$C$2:$C$68,$A7,Tasks!$J$2:$J$68,"In progress") -> 0 | F7: =COUNTIFS(Tasks!$C$2:$C$68,$A7,Tasks!$J$2:$J$68,"Blocked") -> 0 | G7: =IFERROR(SUMIF(Tasks!$C$2:$C$68,$A7,Tasks!$K$2:$K$68)/B7,0) -> 0
A8: 2 - Split | B8: =COUNTIF(Tasks!$C$2:$C$68,$A8) -> 10 | C8: =SUMIF(Tasks!$C$2:$C$68,$A8,Tasks!$H$2:$H$68) -> 7.25 | D8: =COUNTIFS(Tasks!$C$2:$C$68,$A8,Tasks!$J$2:$J$68,"Done") -> 0 | E8: =COUNTIFS(Tasks!$C$2:$C$68,$A8,Tasks!$J$2:$J$68,"In progress") -> 0 | F8: =COUNTIFS(Tasks!$C$2:$C$68,$A8,Tasks!$J$2:$J$68,"Blocked") -> 0 | G8: =IFERROR(SUMIF(Tasks!$C$2:$C$68,$A8,Tasks!$K$2:$K$68)/B8,0) -> 0
A9: 3 - Hardening | B9: =COUNTIF(Tasks!$C$2:$C$68,$A9) -> 11 | C9: =SUMIF(Tasks!$C$2:$C$68,$A9,Tasks!$H$2:$H$68) -> 6.75 | D9: =COUNTIFS(Tasks!$C$2:$C$68,$A9,Tasks!$J$2:$J$68,"Done") -> 0 | E9: =COUNTIFS(Tasks!$C$2:$C$68,$A9,Tasks!$J$2:$J$68,"In progress") -> 0 | F9: =COUNTIFS(Tasks!$C$2:$C$68,$A9,Tasks!$J$2:$J$68,"Blocked") -> 0 | G9: =IFERROR(SUMIF(Tasks!$C$2:$C$68,$A9,Tasks!$K$2:$K$68)/B9,0) -> 0
A10: 4 - Cutover | B10: =COUNTIF(Tasks!$C$2:$C$68,$A10) -> 11 | C10: =SUMIF(Tasks!$C$2:$C$68,$A10,Tasks!$H$2:$H$68) -> 7.25 | D10: =COUNTIFS(Tasks!$C$2:$C$68,$A10,Tasks!$J$2:$J$68,"Done") -> 0 | E10: =COUNTIFS(Tasks!$C$2:$C$68,$A10,Tasks!$J$2:$J$68,"In progress") -> 0 | F10: =COUNTIFS(Tasks!$C$2:$C$68,$A10,Tasks!$J$2:$J$68,"Blocked") -> 0 | G10: =IFERROR(SUMIF(Tasks!$C$2:$C$68,$A10,Tasks!$K$2:$K$68)/B10,0) -> 0
A11: 5 - PHI (outside window) | B11: =COUNTIF(Tasks!$C$2:$C$68,$A11) -> 11 | C11: =SUMIF(Tasks!$C$2:$C$68,$A11,Tasks!$H$2:$H$68) -> 33 | D11: =COUNTIFS(Tasks!$C$2:$C$68,$A11,Tasks!$J$2:$J$68,"Done") -> 0 | E11: =COUNTIFS(Tasks!$C$2:$C$68,$A11,Tasks!$J$2:$J$68,"In progress") -> 0 | F11: =COUNTIFS(Tasks!$C$2:$C$68,$A11,Tasks!$J$2:$J$68,"Blocked") -> 0 | G11: =IFERROR(SUMIF(Tasks!$C$2:$C$68,$A11,Tasks!$K$2:$K$68)/B11,0) -> 0
A12: 6 - Real data (outside window) | B12: =COUNTIF(Tasks!$C$2:$C$68,$A12) -> 7 | C12: =SUMIF(Tasks!$C$2:$C$68,$A12,Tasks!$H$2:$H$68) -> 15.5 | D12: =COUNTIFS(Tasks!$C$2:$C$68,$A12,Tasks!$J$2:$J$68,"Done") -> 0 | E12: =COUNTIFS(Tasks!$C$2:$C$68,$A12,Tasks!$J$2:$J$68,"In progress") -> 0 | F12: =COUNTIFS(Tasks!$C$2:$C$68,$A12,Tasks!$J$2:$J$68,"Blocked") -> 0 | G12: =IFERROR(SUMIF(Tasks!$C$2:$C$68,$A12,Tasks!$K$2:$K$68)/B12,0) -> 0
A13: Total | B13: =SUM(B6:B12) -> 67 | C13: =SUM(C6:C12) -> 76.75 | D13: =SUM(D6:D12) -> 0 | E13: =SUM(E6:E12) -> 0 | F13: =SUM(F6:F12) -> 0 | G13: =IFERROR(SUM(Tasks!$K$2:$K$68)/B13,0) -> 0
A15: Capacity check
A16: In-window estimate (Phases 0-4) | B16: =C13-C11-C12 -> 28.25
A17: Capacity: 30 working days x 2 devs x 50% | B17: 30
A18: Headroom (days) | B18: =B17-B16 -> 1.75
A19: Phase 5 - PHI, not in this window | B19: =C11 -> 33
A20: Phase 6 - real data, not in this window | B20: =C12 -> 15.5
A22: By track
A23: Track | B23: Tasks | C23: Est (days) | D23: Done | E23: % complete
A24: Platform | B24: =COUNTIF(Tasks!$D$2:$D$68,$A24) -> 30 | C24: =SUMIF(Tasks!$D$2:$D$68,$A24,Tasks!$H$2:$H$68) -> 33.25 | D24: =COUNTIFS(Tasks!$D$2:$D$68,$A24,Tasks!$J$2:$J$68,"Done") -> 0 | E24: =IFERROR(SUMIF(Tasks!$D$2:$D$68,$A24,Tasks!$K$2:$K$68)/B24,0) -> 0
A25: Application | B25: =COUNTIF(Tasks!$D$2:$D$68,$A25) -> 21 | C25: =SUMIF(Tasks!$D$2:$D$68,$A25,Tasks!$H$2:$H$68) -> 36.5 | D25: =COUNTIFS(Tasks!$D$2:$D$68,$A25,Tasks!$J$2:$J$68,"Done") -> 0 | E25: =IFERROR(SUMIF(Tasks!$D$2:$D$68,$A25,Tasks!$K$2:$K$68)/B25,0) -> 0
A26: Both | B26: =COUNTIF(Tasks!$D$2:$D$68,$A26) -> 13 | C26: =SUMIF(Tasks!$D$2:$D$68,$A26,Tasks!$H$2:$H$68) -> 6 | D26: =COUNTIFS(Tasks!$D$2:$D$68,$A26,Tasks!$J$2:$J$68,"Done") -> 0 | E26: =IFERROR(SUMIF(Tasks!$D$2:$D$68,$A26,Tasks!$K$2:$K$68)/B26,0) -> 0
A27: Compliance | B27: =COUNTIF(Tasks!$D$2:$D$68,$A27) -> 3 | C27: =SUMIF(Tasks!$D$2:$D$68,$A27,Tasks!$H$2:$H$68) -> 1 | D27: =COUNTIFS(Tasks!$D$2:$D$68,$A27,Tasks!$J$2:$J$68,"Done") -> 0 | E27: =IFERROR(SUMIF(Tasks!$D$2:$D$68,$A27,Tasks!$K$2:$K$68)/B27,0) -> 0
A29: Effort
A30: Estimated (all phases) | B30: =SUM(Tasks!$H$2:$H$68) -> 76.75
A31: Actual logged | B31: =SUM(Tasks!$L$2:$L$68) -> 0
A32: Variance (actual - estimate) | B32: =B31-B30 -> -76.75
A34: How to use this
A35: Edit only the yellow cells: Status, % complete, Actual days, Notes.
A36: Everything on this sheet is a formula and follows automatically.
A37: Green rows are milestones. Amber rows are gates - a gate not met blocks what follows.
A38: Phase 5 carries no dates: it is outside this window and starts with a contract, not code.
A39: The hard rule: no production PHI until P1-P6 are Done.
